<?xml version="1.0" ?>
<!-- =================================================================================== -->
<!-- |    This document was autogenerated by xacro from src/skt_description/robot/skt.xacro | -->
<!-- |    EDITING THIS FILE BY HAND IS NOT RECOMMENDED                                 | -->
<!-- =================================================================================== -->
<robot name="skt">
  <!-- Read in the yaml dict as mp (short for model parameters) -->
  <link name="base_link">
    <visual>
      <origin rpy="0.0 0.0 1.5707963267948966" xyz="0.0 0.0 -0.018"/>
      <geometry>
        <mesh filename="package://skt_description/meshes/skt_body.stl"/>
      </geometry>
      <material name="chassis_color">
        <color rgba="1 1 1 1"/>
      </material>
    </visual>
  </link>
  <link name="base_footprint"/>
  <joint name="base_offset" type="fixed">
    <parent link="base_footprint"/>
    <child link="base_link"/>
    <origin xyz="0.0 0.0 0.165"/>
  </joint>
  <link name="left_wheel">
    <visual>
      <origin rpy="0.0 0.0 0.0" xyz="0.0 0.0 0.0"/>
      <geometry>
        <cylinder length="0.04" radius="0.08"/>
      </geometry>
      <material name="left_wheel_color">
        <color rgba="0 0 0 1"/>
      </material>
    </visual>
  </link>
  <joint name="left_wheel_joint" type="continuous">
    <origin rpy="-1.5707963267948966 0.0 0.0" xyz="0.0 0.225 -0.085"/>
    <parent link="base_link"/>
    <child link="left_wheel"/>
    <axis xyz="0.0 0.0 1.0"/>
    <joint_properties damping="1.0" friction="1.0"/>
  </joint>
  <link name="right_wheel">
    <visual>
      <origin rpy="0.0 0.0 0.0" xyz="0.0 0.0 0.0"/>
      <geometry>
        <cylinder length="0.04" radius="0.08"/>
      </geometry>
      <material name="right_wheel_color">
        <color rgba="0 0 0 1"/>
      </material>
    </visual>
  </link>
  <joint name="right_wheel_joint" type="continuous">
    <origin rpy="-1.5707963267948966 0.0 0.0" xyz="0.0 -0.225 -0.085"/>
    <parent link="base_link"/>
    <child link="right_wheel"/>
    <axis xyz="0.0 0.0 1.0"/>
    <joint_properties damping="1.0" friction="1.0"/>
  </joint>
  
  <link name="imu_link"/>
  <joint name="imu_mount" type="fixed">
    <parent link="base_link"/>
    <child link="imu_link"/>
    <origin rpy="0 0 0" xyz="0 0 0"/>
  </joint>
</robot>
